2025-09-24 16:09:54,467 - [WARNING] - discord.client: PyNaCl is not installed, voice will NOT be supported
2025-09-24 16:09:54,467 - [INFO] - discord.client: logging in using static token
2025-09-24 16:09:58,769 - [INFO] - __main__: --- Starting Bot Setup ---
2025-09-24 16:09:58,770 - [INFO] - cogs.utils.db: Database has been successfully initialized.
2025-09-24 16:09:58,819 - [INFO] - cogs.handler: Successfully loaded extension: cogs.commands.avatar
2025-09-24 16:09:58,826 - [INFO] - cogs.handler: Successfully loaded extension: cogs.commands.botinfo
2025-09-24 16:09:59,314 - [INFO] - cogs.commands.chat: Gemini AI model has been successfully configured.
2025-09-24 16:09:59,315 - [INFO] - cogs.handler: Successfully loaded extension: cogs.commands.chat
2025-09-24 16:09:59,323 - [INFO] - cogs.handler: Successfully loaded extension: cogs.commands.clear
2025-09-24 16:09:59,324 - [INFO] - cogs.handler: Successfully loaded extension: cogs.commands.config
2025-09-24 16:09:59,325 - [INFO] - cogs.handler: Successfully loaded extension: cogs.commands.help
2025-09-24 16:09:59,326 - [INFO] - cogs.handler: Successfully loaded extension: cogs.commands.invite
2025-09-24 16:09:59,335 - [INFO] - cogs.handler: Successfully loaded extension: cogs.commands.ping
2025-09-24 16:09:59,342 - [INFO] - cogs.handler: Successfully loaded extension: cogs.commands.serverinfo
2025-09-24 16:09:59,351 - [INFO] - cogs.handler: Successfully loaded extension: cogs.commands.setup
2025-09-24 16:09:59,358 - [INFO] - cogs.handler: Successfully loaded extension: cogs.commands.userinfo
2025-09-24 16:09:59,395 - [INFO] - cogs.handler: Successfully loaded extension: cogs.events.members
2025-09-24 16:09:59,396 - [ERROR] - cogs.handler: Failed to load extension cogs.utils.db: Extension 'cogs.utils.db' has no 'setup' function.
Traceback (most recent call last):
  File "C:\Users\User\AppData\Local\Packages\PythonSoftwareFoundation.Python.3.11_qbz5n2kfra8p0\LocalCache\local-packages\Python311\site-packages\discord\ext\commands\bot.py", line 968, in _load_from_module_spec
    setup = getattr(lib, 'setup')
            ^^^^^^^^^^^^^^^^^^^^^
AttributeError: module 'cogs.utils.db' has no attribute 'setup'

During handling of the above exception, another exception occurred:

Traceback (most recent call last):
  File "Z:\#Files\Desktop\Tilt-bot-main\cogs\handler.py", line 35, in cog_load
    await self.bot.load_extension(extension_name)
  File "C:\Users\User\AppData\Local\Packages\PythonSoftwareFoundation.Python.3.11_qbz5n2kfra8p0\LocalCache\local-packages\Python311\site-packages\discord\ext\commands\bot.py", line 1040, in load_extension
    await self._load_from_module_spec(spec, name)
  File "C:\Users\User\AppData\Local\Packages\PythonSoftwareFoundation.Python.3.11_qbz5n2kfra8p0\LocalCache\local-packages\Python311\site-packages\discord\ext\commands\bot.py", line 971, in _load_from_module_spec
    raise errors.NoEntryPointError(key)
discord.ext.commands.errors.NoEntryPointError: Extension 'cogs.utils.db' has no 'setup' function.
2025-09-24 16:09:59,863 - [INFO] - __main__: Successfully synced 11 application commands.
2025-09-24 16:10:04,345 - [INFO] - discord.gateway: Shard ID None has connected to Gateway (Session ID: 2ff434b3a3ddcf4560b2f159d0496cfb).
2025-09-24 16:10:42,380 - [ERROR] - discord.app_commands.tree: Ignoring exception in command 'help'
Traceback (most recent call last):
  File "C:\Users\User\AppData\Local\Packages\PythonSoftwareFoundation.Python.3.11_qbz5n2kfra8p0\LocalCache\local-packages\Python311\site-packages\discord\app_commands\commands.py", line 858, in _do_call
    return await self._callback(self.binding, interaction, **params)  # type: ignore
           ^^^^^^^^^^^^^^^^^^^^^^^^^^^^^^^^^^^^^^^^^^^^^^^^^^^^^^^^^
  File "Z:\#Files\Desktop\Tilt-bot-main\cogs\commands\help.py", line 14, in help
    await interaction.response.defer(ephemeral=True)
  File "C:\Users\User\AppData\Local\Packages\PythonSoftwareFoundation.Python.3.11_qbz5n2kfra8p0\LocalCache\local-packages\Python311\site-packages\discord\interactions.py", line 858, in defer
    response = await adapter.create_interaction_response(
               ^^^^^^^^^^^^^^^^^^^^^^^^^^^^^^^^^^^^^^^^^^
  File "C:\Users\User\AppData\Local\Packages\PythonSoftwareFoundation.Python.3.11_qbz5n2kfra8p0\LocalCache\local-packages\Python311\site-packages\discord\webhook\async_.py", line 224, in request
    raise NotFound(response, data)
discord.errors.NotFound: 404 Not Found (error code: 10062): Unknown interaction

The above exception was the direct cause of the following exception:

Traceback (most recent call last):
  File "C:\Users\User\AppData\Local\Packages\PythonSoftwareFoundation.Python.3.11_qbz5n2kfra8p0\LocalCache\local-packages\Python311\site-packages\discord\app_commands\tree.py", line 1297, in _call
    await command._invoke_with_namespace(interaction, namespace)
  File "C:\Users\User\AppData\Local\Packages\PythonSoftwareFoundation.Python.3.11_qbz5n2kfra8p0\LocalCache\local-packages\Python311\site-packages\discord\app_commands\commands.py", line 884, in _invoke_with_namespace
    return await self._do_call(interaction, transformed_values)
           ^^^^^^^^^^^^^^^^^^^^^^^^^^^^^^^^^^^^^^^^^^^^^^^^^^^^
  File "C:\Users\User\AppData\Local\Packages\PythonSoftwareFoundation.Python.3.11_qbz5n2kfra8p0\LocalCache\local-packages\Python311\site-packages\discord\app_commands\commands.py", line 877, in _do_call
    raise CommandInvokeError(self, e) from e
discord.app_commands.errors.CommandInvokeError: Command 'help' raised an exception: NotFound: 404 Not Found (error code: 10062): Unknown interaction
2025-09-24 16:10:53,397 - [INFO] - cogs.commands.clear: tiltedblock cleared 10 messages in #commands (TiltedBlock HQ).
2025-09-24 16:12:29,552 - [WARNING] - discord.client: PyNaCl is not installed, voice will NOT be supported
2025-09-24 16:12:29,554 - [INFO] - discord.client: logging in using static token
2025-09-24 16:12:33,888 - [INFO] - __main__: --- Starting Bot Setup ---
2025-09-24 16:12:33,888 - [INFO] - cogs.utils.db: Database has been successfully initialized.
2025-09-24 16:12:33,888 - [INFO] - cogs.handler: --- Loading Extensions ---
2025-09-24 16:12:33,888 - [ERROR] - cogs.handler: Failed to load extension cogs.commands.avatar: name 'asyncio' is not defined
Traceback (most recent call last):
  File "Z:\#Files\Desktop\Tilt-bot-main\cogs\handler.py", line 37, in load_all_extensions
    asyncio.run_coroutine_threadsafe(
    ^^^^^^^
NameError: name 'asyncio' is not defined
2025-09-24 16:12:33,888 - [ERROR] - cogs.handler: Failed to load extension cogs.commands.botinfo: name 'asyncio' is not defined
Traceback (most recent call last):
  File "Z:\#Files\Desktop\Tilt-bot-main\cogs\handler.py", line 37, in load_all_extensions
    asyncio.run_coroutine_threadsafe(
    ^^^^^^^
NameError: name 'asyncio' is not defined
2025-09-24 16:12:33,904 - [ERROR] - cogs.handler: Failed to load extension cogs.commands.chat: name 'asyncio' is not defined
Traceback (most recent call last):
  File "Z:\#Files\Desktop\Tilt-bot-main\cogs\handler.py", line 37, in load_all_extensions
    asyncio.run_coroutine_threadsafe(
    ^^^^^^^
NameError: name 'asyncio' is not defined
2025-09-24 16:12:33,905 - [ERROR] - cogs.handler: Failed to load extension cogs.commands.clear: name 'asyncio' is not defined
Traceback (most recent call last):
  File "Z:\#Files\Desktop\Tilt-bot-main\cogs\handler.py", line 37, in load_all_extensions
    asyncio.run_coroutine_threadsafe(
    ^^^^^^^
NameError: name 'asyncio' is not defined
2025-09-24 16:12:33,905 - [ERROR] - cogs.handler: Failed to load extension cogs.commands.config: name 'asyncio' is not defined
Traceback (most recent call last):
  File "Z:\#Files\Desktop\Tilt-bot-main\cogs\handler.py", line 37, in load_all_extensions
    asyncio.run_coroutine_threadsafe(
    ^^^^^^^
NameError: name 'asyncio' is not defined
2025-09-24 16:12:33,905 - [ERROR] - cogs.handler: Failed to load extension cogs.commands.help: name 'asyncio' is not defined
Traceback (most recent call last):
  File "Z:\#Files\Desktop\Tilt-bot-main\cogs\handler.py", line 37, in load_all_extensions
    asyncio.run_coroutine_threadsafe(
    ^^^^^^^
NameError: name 'asyncio' is not defined
2025-09-24 16:12:33,905 - [ERROR] - cogs.handler: Failed to load extension cogs.commands.invite: name 'asyncio' is not defined
Traceback (most recent call last):
  File "Z:\#Files\Desktop\Tilt-bot-main\cogs\handler.py", line 37, in load_all_extensions
    asyncio.run_coroutine_threadsafe(
    ^^^^^^^
NameError: name 'asyncio' is not defined
2025-09-24 16:12:33,905 - [ERROR] - cogs.handler: Failed to load extension cogs.commands.ping: name 'asyncio' is not defined
Traceback (most recent call last):
  File "Z:\#Files\Desktop\Tilt-bot-main\cogs\handler.py", line 37, in load_all_extensions
    asyncio.run_coroutine_threadsafe(
    ^^^^^^^
NameError: name 'asyncio' is not defined
2025-09-24 16:12:33,907 - [ERROR] - cogs.handler: Failed to load extension cogs.commands.serverinfo: name 'asyncio' is not defined
Traceback (most recent call last):
  File "Z:\#Files\Desktop\Tilt-bot-main\cogs\handler.py", line 37, in load_all_extensions
    asyncio.run_coroutine_threadsafe(
    ^^^^^^^
NameError: name 'asyncio' is not defined
2025-09-24 16:12:33,907 - [ERROR] - cogs.handler: Failed to load extension cogs.commands.setup: name 'asyncio' is not defined
Traceback (most recent call last):
  File "Z:\#Files\Desktop\Tilt-bot-main\cogs\handler.py", line 37, in load_all_extensions
    asyncio.run_coroutine_threadsafe(
    ^^^^^^^
NameError: name 'asyncio' is not defined
2025-09-24 16:12:33,907 - [ERROR] - cogs.handler: Failed to load extension cogs.commands.userinfo: name 'asyncio' is not defined
Traceback (most recent call last):
  File "Z:\#Files\Desktop\Tilt-bot-main\cogs\handler.py", line 37, in load_all_extensions
    asyncio.run_coroutine_threadsafe(
    ^^^^^^^
NameError: name 'asyncio' is not defined
2025-09-24 16:12:33,908 - [ERROR] - cogs.handler: Failed to load extension cogs.events.members: name 'asyncio' is not defined
Traceback (most recent call last):
  File "Z:\#Files\Desktop\Tilt-bot-main\cogs\handler.py", line 37, in load_all_extensions
    asyncio.run_coroutine_threadsafe(
    ^^^^^^^
NameError: name 'asyncio' is not defined
2025-09-24 16:12:34,349 - [INFO] - __main__: Successfully synced 0 application commands.
2025-09-24 16:12:38,483 - [INFO] - discord.gateway: Shard ID None has connected to Gateway (Session ID: 3ee0ee9f5d51b2a000a08a46c304e804).
2025-09-24 16:12:40,500 - [INFO] - __main__: Logged in as Tilt-bot#9361 (ID: 1417562386138923270)
2025-09-24 16:12:40,500 - [INFO] - __main__: Bot is in 1 guilds.
2025-09-24 16:12:58,935 - [INFO] - __main__: Bot has been shut down.
2025-09-24 16:13:52,100 - [WARNING] - discord.client: PyNaCl is not installed, voice will NOT be supported
2025-09-24 16:13:52,100 - [INFO] - discord.client: logging in using static token
2025-09-24 16:13:56,312 - [INFO] - __main__: --- Starting Bot Setup ---
2025-09-24 16:13:56,312 - [INFO] - cogs.utils.db: Database has been successfully initialized.
2025-09-24 16:13:56,347 - [INFO] - cogs.handler: --- Loading Extensions ---
2025-09-24 16:13:56,347 - [INFO] - cogs.handler: Successfully loaded extension: cogs.commands.avatar
2025-09-24 16:13:56,347 - [INFO] - cogs.handler: Successfully loaded extension: cogs.commands.botinfo
2025-09-24 16:13:56,348 - [INFO] - cogs.handler: Successfully loaded extension: cogs.commands.chat
2025-09-24 16:13:56,348 - [INFO] - cogs.handler: Successfully loaded extension: cogs.commands.clear
2025-09-24 16:13:56,348 - [INFO] - cogs.handler: Successfully loaded extension: cogs.commands.config
2025-09-24 16:13:56,348 - [INFO] - cogs.handler: Successfully loaded extension: cogs.commands.help
2025-09-24 16:13:56,348 - [INFO] - cogs.handler: Successfully loaded extension: cogs.commands.invite
2025-09-24 16:13:56,349 - [INFO] - cogs.handler: Successfully loaded extension: cogs.commands.ping
2025-09-24 16:13:56,349 - [INFO] - cogs.handler: Successfully loaded extension: cogs.commands.serverinfo
2025-09-24 16:13:56,349 - [INFO] - cogs.handler: Successfully loaded extension: cogs.commands.setup
2025-09-24 16:13:56,349 - [INFO] - cogs.handler: Successfully loaded extension: cogs.commands.userinfo
2025-09-24 16:13:56,349 - [INFO] - cogs.handler: Successfully loaded extension: cogs.events.members
2025-09-24 16:13:56,871 - [INFO] - cogs.commands.chat: Gemini AI model has been successfully configured.
2025-09-24 16:13:56,879 - [INFO] - __main__: Successfully synced 0 application commands.
2025-09-24 16:14:01,007 - [INFO] - discord.gateway: Shard ID None has connected to Gateway (Session ID: b26c61a38644beabd3c7b307976cf98a).
2025-09-24 16:14:03,007 - [INFO] - __main__: Logged in as Tilt-bot#9361 (ID: 1417562386138923270)
2025-09-24 16:14:03,007 - [INFO] - __main__: Bot is in 1 guilds.
2025-09-24 16:15:02,711 - [INFO] - __main__: Bot has been shut down.
2025-09-24 16:15:26,795 - [WARNING] - discord.client: PyNaCl is not installed, voice will NOT be supported
2025-09-24 16:15:26,796 - [INFO] - discord.client: logging in using static token
2025-09-24 16:15:30,857 - [INFO] - __main__: --- Starting Bot Setup ---
2025-09-24 16:15:30,860 - [INFO] - cogs.utils.db: Database has been successfully initialized.
2025-09-24 16:15:30,867 - [INFO] - cogs.handler: --- Loading Extensions ---
2025-09-24 16:15:30,868 - [INFO] - cogs.handler: Successfully loaded extension: cogs.commands.avatar
2025-09-24 16:15:30,868 - [INFO] - cogs.handler: Successfully loaded extension: cogs.commands.botinfo
2025-09-24 16:15:30,868 - [INFO] - cogs.handler: Successfully loaded extension: cogs.commands.chat
2025-09-24 16:15:30,868 - [INFO] - cogs.handler: Successfully loaded extension: cogs.commands.clear
2025-09-24 16:15:30,868 - [INFO] - cogs.handler: Successfully loaded extension: cogs.commands.config
2025-09-24 16:15:30,868 - [INFO] - cogs.handler: Successfully loaded extension: cogs.commands.help
2025-09-24 16:15:30,869 - [INFO] - cogs.handler: Successfully loaded extension: cogs.commands.invite
2025-09-24 16:15:30,869 - [INFO] - cogs.handler: Successfully loaded extension: cogs.commands.ping
2025-09-24 16:15:30,869 - [INFO] - cogs.handler: Successfully loaded extension: cogs.commands.serverinfo
2025-09-24 16:15:30,869 - [INFO] - cogs.handler: Successfully loaded extension: cogs.commands.setup
2025-09-24 16:15:30,869 - [INFO] - cogs.handler: Successfully loaded extension: cogs.commands.userinfo
2025-09-24 16:15:30,869 - [INFO] - cogs.handler: Successfully loaded extension: cogs.events.members
2025-09-24 16:15:31,368 - [INFO] - cogs.commands.chat: Gemini AI model has been successfully configured.
2025-09-24 16:15:31,376 - [INFO] - __main__: Successfully synced 0 application commands.
2025-09-24 16:15:35,474 - [INFO] - discord.gateway: Shard ID None has connected to Gateway (Session ID: fdcd5b046f9acd09dd9e1d71193067eb).
2025-09-24 16:15:37,477 - [INFO] - __main__: Logged in as Tilt-bot#9361 (ID: 1417562386138923270)
2025-09-24 16:15:37,477 - [INFO] - __main__: Bot is in 1 guilds.
2025-09-24 16:19:00,218 - [INFO] - __main__: Bot has been shut down.
