2025-09-24 16:52:00,460 - [WARNING] - discord.client: PyNaCl is not installed, voice will NOT be supported
2025-09-24 16:52:00,460 - [INFO] - discord.client: logging in using static token
2025-09-24 16:52:04,799 - [INFO] - __main__: --- Starting Bot Setup ---
2025-09-24 16:52:04,801 - [INFO] - cogs.utils.db: Database has been successfully initialized.
2025-09-24 16:52:04,824 - [INFO] - cogs.handler: --- Loading Extensions ---
2025-09-24 16:52:04,824 - [INFO] - cogs.handler: Successfully loaded extension: cogs.commands.avatar
2025-09-24 16:52:04,824 - [INFO] - cogs.handler: Successfully loaded extension: cogs.commands.botinfo
2025-09-24 16:52:04,825 - [INFO] - cogs.handler: Successfully loaded extension: cogs.commands.chat
2025-09-24 16:52:04,825 - [INFO] - cogs.handler: Successfully loaded extension: cogs.commands.clear
2025-09-24 16:52:04,825 - [INFO] - cogs.handler: Successfully loaded extension: cogs.commands.config
2025-09-24 16:52:04,825 - [INFO] - cogs.handler: Successfully loaded extension: cogs.commands.help
2025-09-24 16:52:04,825 - [INFO] - cogs.handler: Successfully loaded extension: cogs.commands.invite
2025-09-24 16:52:04,826 - [INFO] - cogs.handler: Successfully loaded extension: cogs.commands.ping
2025-09-24 16:52:04,826 - [INFO] - cogs.handler: Successfully loaded extension: cogs.commands.serverinfo
2025-09-24 16:52:04,826 - [INFO] - cogs.handler: Successfully loaded extension: cogs.commands.setup
2025-09-24 16:52:04,826 - [INFO] - cogs.handler: Successfully loaded extension: cogs.commands.userinfo
2025-09-24 16:52:04,826 - [INFO] - cogs.handler: Successfully loaded extension: cogs.events.members
2025-09-24 16:52:05,323 - [INFO] - cogs.commands.chat: Gemini AI model has been successfully configured.
2025-09-24 16:52:05,346 - [INFO] - __main__: Successfully synced 0 application commands.
2025-09-24 16:52:09,618 - [INFO] - discord.gateway: Shard ID None has connected to Gateway (Session ID: 9ea83020534b0538b6d510a426db507e).
2025-09-24 16:52:11,629 - [INFO] - __main__: Logged in as Tilt-bot#9361 (ID: 1417562386138923270)
2025-09-24 16:52:11,629 - [INFO] - __main__: Bot is in 1 guilds.
2025-09-24 16:52:30,151 - [INFO] - __main__: Bot has been shut down.
2025-09-24 16:52:34,158 - [WARNING] - discord.client: PyNaCl is not installed, voice will NOT be supported
2025-09-24 16:52:34,158 - [INFO] - discord.client: logging in using static token
2025-09-24 16:52:38,388 - [INFO] - __main__: --- Starting Bot Setup ---
2025-09-24 16:52:38,390 - [INFO] - cogs.utils.db: Database has been successfully initialized.
2025-09-24 16:52:38,402 - [INFO] - cogs.handler: --- Loading Extensions ---
2025-09-24 16:52:38,404 - [INFO] - cogs.handler: Successfully loaded extension: cogs.commands.avatar
2025-09-24 16:52:38,405 - [INFO] - cogs.handler: Successfully loaded extension: cogs.commands.botinfo
2025-09-24 16:52:38,885 - [INFO] - cogs.commands.chat: Gemini AI model has been successfully configured.
2025-09-24 16:52:38,885 - [INFO] - cogs.handler: Successfully loaded extension: cogs.commands.chat
2025-09-24 16:52:38,899 - [INFO] - cogs.handler: Successfully loaded extension: cogs.commands.clear
2025-09-24 16:52:38,899 - [INFO] - cogs.handler: Successfully loaded extension: cogs.commands.config
2025-09-24 16:52:38,899 - [INFO] - cogs.handler: Successfully loaded extension: cogs.commands.help
2025-09-24 16:52:38,908 - [INFO] - cogs.handler: Successfully loaded extension: cogs.commands.invite
2025-09-24 16:52:38,908 - [INFO] - cogs.handler: Successfully loaded extension: cogs.commands.ping
2025-09-24 16:52:38,909 - [INFO] - cogs.handler: Successfully loaded extension: cogs.commands.serverinfo
2025-09-24 16:52:38,911 - [INFO] - cogs.handler: Successfully loaded extension: cogs.commands.setup
2025-09-24 16:52:38,912 - [INFO] - cogs.handler: Successfully loaded extension: cogs.commands.userinfo
2025-09-24 16:52:38,914 - [INFO] - cogs.handler: Successfully loaded extension: cogs.events.members
2025-09-24 16:52:38,938 - [INFO] - cogs.handler: Successfully loaded extension: cogs.error_handler
2025-09-24 16:52:39,471 - [INFO] - __main__: Successfully synced 11 application commands.
2025-09-24 16:52:43,714 - [INFO] - discord.gateway: Shard ID None has connected to Gateway (Session ID: 57724bc4946e17a85de09133f08685c5).
2025-09-24 16:52:45,725 - [INFO] - __main__: Logged in as Tilt-bot#9361 (ID: 1417562386138923270)
2025-09-24 16:52:45,726 - [INFO] - __main__: Bot is in 1 guilds.
2025-09-24 16:53:35,194 - [ERROR] - cogs.error_handler: Error in command 'help': Command 'help' raised an exception: NotFound: 404 Not Found (error code: 10062): Unknown interaction
Traceback (most recent call last):
  File "C:\Users\User\AppData\Local\Packages\PythonSoftwareFoundation.Python.3.11_qbz5n2kfra8p0\LocalCache\local-packages\Python311\site-packages\discord\app_commands\commands.py", line 858, in _do_call
    return await self._callback(self.binding, interaction, **params)  # type: ignore
           ^^^^^^^^^^^^^^^^^^^^^^^^^^^^^^^^^^^^^^^^^^^^^^^^^^^^^^^^^
  File "Z:\#Files\Desktop\Tilt-bot-main\cogs\commands\help.py", line 80, in help
    await interaction.response.defer(ephemeral=True)
  File "C:\Users\User\AppData\Local\Packages\PythonSoftwareFoundation.Python.3.11_qbz5n2kfra8p0\LocalCache\local-packages\Python311\site-packages\discord\interactions.py", line 858, in defer
    response = await adapter.create_interaction_response(
               ^^^^^^^^^^^^^^^^^^^^^^^^^^^^^^^^^^^^^^^^^^
  File "C:\Users\User\AppData\Local\Packages\PythonSoftwareFoundation.Python.3.11_qbz5n2kfra8p0\LocalCache\local-packages\Python311\site-packages\discord\webhook\async_.py", line 224, in request
    raise NotFound(response, data)
discord.errors.NotFound: 404 Not Found (error code: 10062): Unknown interaction

The above exception was the direct cause of the following exception:

Traceback (most recent call last):
  File "C:\Users\User\AppData\Local\Packages\PythonSoftwareFoundation.Python.3.11_qbz5n2kfra8p0\LocalCache\local-packages\Python311\site-packages\discord\app_commands\tree.py", line 1297, in _call
    await command._invoke_with_namespace(interaction, namespace)
  File "C:\Users\User\AppData\Local\Packages\PythonSoftwareFoundation.Python.3.11_qbz5n2kfra8p0\LocalCache\local-packages\Python311\site-packages\discord\app_commands\commands.py", line 884, in _invoke_with_namespace
    return await self._do_call(interaction, transformed_values)
           ^^^^^^^^^^^^^^^^^^^^^^^^^^^^^^^^^^^^^^^^^^^^^^^^^^^^
  File "C:\Users\User\AppData\Local\Packages\PythonSoftwareFoundation.Python.3.11_qbz5n2kfra8p0\LocalCache\local-packages\Python311\site-packages\discord\app_commands\commands.py", line 877, in _do_call
    raise CommandInvokeError(self, e) from e
discord.app_commands.errors.CommandInvokeError: Command 'help' raised an exception: NotFound: 404 Not Found (error code: 10062): Unknown interaction
2025-09-24 16:53:35,465 - [ERROR] - cogs.error_handler: Failed to send error message to user: 404 Not Found (error code: 10062): Unknown interaction
